#VRML_SIM R2022a utf8
WorldInfo {
  contactProperties [
    ContactProperties {
      material1 "wheel"
      material2 "floor"
      coulombFriction [
        999999
      ]
    }
  ]
}
Viewpoint {
  orientation -0.35267379707985985 0.015200290488353866 0.9356228642045595 3.1711573499281105
  position 1.7959284918657072 0.32997881968978904 1.2889018652737287
}
TexturedBackground {
}
TexturedBackgroundLight {
}
CircleArena {
  contactMaterial "floor"
  wallHeight 0.5
}
Robot {
  children [
    Solid {
      translation 0 0 0.023249
      children [
        HingeJoint {
          jointParameters HingeJointParameters {
            axis 0 1 0
            anchor -0.081663 0.08105 0.01575
          }
          device [
            RotationalMotor {
              name "left_rear_wheel_joint"
              maxVelocity 100
              minPosition -1
              maxPosition 1
            }
            PositionSensor {
              name "left_rear_wheel_joint_sensor"
            }
          ]
          endPoint Solid {
            translation -0.081663 0.08105 0.01575
            children [
              Transform {
                rotation -0.5773129352569557 0.5773689352506757 0.5773689352506757 2.094284
                children [
                  Shape {
                    appearance PBRAppearance {
                      baseColor 0.5 0.5 0.5
                      roughness 1
                      metalness 0
                    }
                    geometry Cylinder {
                      height 0.025
                      radius 0.03
                    }
                  }
                ]
              }
            ]
            name "left_rear_wheel"
            contactMaterial "wheel"
            boundingObject Transform {
              rotation -0.5773129352569557 0.5773689352506757 0.5773689352506757 2.094284
              children [
                Cylinder {
                  height 0.025
                  radius 0.03
                }
              ]
            }
            physics Physics {
              density -1
              mass 0.042222
              centerOfMass [
                0 0 0
              ]
              inertiaMatrix [
                9.44606e-05 6.11771e-05 6.11771e-05
                -2.083948e-20 -3.206093e-09 7.972411e-21
              ]
            }
          }
        }
        HingeJoint {
          jointParameters HingeJointParameters {
            axis 0 1 0
            anchor -0.081663 -0.08105 0.01575
          }
          device [
            RotationalMotor {
              name "right_rear_wheel_joint"
              maxVelocity 100
              minPosition -1
              maxPosition 1
            }
            PositionSensor {
              name "right_rear_wheel_joint_sensor"
            }
          ]
          endPoint Solid {
            translation -0.081663 -0.08105 0.01575
            children [
              Transform {
                rotation -0.5773129352569557 0.5773689352506757 0.5773689352506757 2.094284
                children [
                  Shape {
                    appearance PBRAppearance {
                      baseColor 0.5 0.5 0.5
                      roughness 1
                      metalness 0
                    }
                    geometry Cylinder {
                      height 0.025
                      radius 0.03
                    }
                  }
                ]
              }
            ]
            name "right_rear_wheel"
            contactMaterial "wheel"
            boundingObject Transform {
              rotation -0.5773129352569557 0.5773689352506757 0.5773689352506757 2.094284
              children [
                Cylinder {
                  height 0.025
                  radius 0.03
                }
              ]
            }
            physics Physics {
              density -1
              mass 0.042222
              centerOfMass [
                0 0 0
              ]
              inertiaMatrix [
                9.44606e-05 6.11771e-05 6.11771e-05
                -2.083948e-20 -3.206093e-09 7.972411e-21
              ]
            }
          }
        }
        HingeJoint {
          jointParameters HingeJointParameters {
            axis 0 0 1
            anchor 0.082311 0.079601 0.011759
          }
          device [
            RotationalMotor {
              name "left_steering_hinge_joint"
              maxVelocity 100
              minPosition -1
              maxPosition 1
            }
            PositionSensor {
              name "left_steering_hinge_joint_sensor"
            }
          ]
          endPoint Solid {
            translation 0.082311 0.079601 0.011759
            children [
              Shape {
                appearance PBRAppearance {
                  baseColor 0.5 0.5 0.5
                  roughness 1
                  metalness 0
                }
                geometry DEF left_steering_hinge Mesh {
                  url [
                    "/mnt/d/DeepRacer/CAIRORacer/deepracer_ws/install/deepracer_description/share/deepracer_description/meshes/left_steering_hinge.STL"
                  ]
                }
              }
              HingeJoint {
                jointParameters HingeJointParameters {
                  axis 0 1 0
                }
                device [
                  RotationalMotor {
                    name "left_front_wheel_joint"
                    maxVelocity 100
                    minPosition -1
                    maxPosition 1
                  }
                  PositionSensor {
                    name "left_front_wheel_joint_sensor"
                  }
                ]
                endPoint Solid {
                  children [
                    Transform {
                      rotation -0.5773129352569557 0.5773689352506757 0.5773689352506757 2.094284
                      children [
                        Shape {
                          appearance PBRAppearance {
                            baseColor 0.5 0.5 0.5
                            roughness 1
                            metalness 0
                          }
                          geometry Cylinder {
                            height 0.025
                            radius 0.03
                          }
                        }
                      ]
                    }
                  ]
                  name "left_front_wheel"
                  contactMaterial "wheel"
                  boundingObject Transform {
                    rotation -0.5773129352569557 0.5773689352506757 0.5773689352506757 2.094284
                    children [
                      Cylinder {
                        height 0.025
                        radius 0.03
                      }
                    ]
                  }
                  physics Physics {
                    density -1
                    mass 0.042222
                    centerOfMass [
                      0 0 0
                    ]
                    inertiaMatrix [
                      9.44606e-05 6.11771e-05 6.11771e-05
                      -2.083948e-20 -3.206093e-09 7.972411e-21
                    ]
                  }
                }
              }
            ]
            name "left_steering_hinge"
            physics Physics {
              density -1
              mass 0.05
              centerOfMass [
                0 0 0
              ]
              inertiaMatrix [
                4e-06 4e-06 4e-06
                0 0 0
              ]
            }
          }
        }
        HingeJoint {
          jointParameters HingeJointParameters {
            axis 0 0 1
            anchor 0.082311 -0.079601 0.011759
          }
          device [
            RotationalMotor {
              name "right_steering_hinge_joint"
              maxVelocity 100
              minPosition -1
              maxPosition 1
            }
            PositionSensor {
              name "right_steering_hinge_joint_sensor"
            }
          ]
          endPoint Solid {
            translation 0.082311 -0.079601 0.011759
            children [
              Shape {
                appearance PBRAppearance {
                  baseColor 0.5 0.5 0.5
                  roughness 1
                  metalness 0
                }
                geometry DEF right_steering_hinge Mesh {
                  url [
                    "/mnt/d/DeepRacer/CAIRORacer/deepracer_ws/install/deepracer_description/share/deepracer_description/meshes/right_steering_hinge.STL"
                  ]
                }
              }
              HingeJoint {
                jointParameters HingeJointParameters {
                  axis 0 1 0
                }
                device [
                  RotationalMotor {
                    name "right_front_wheel_joint"
                    maxVelocity 100
                    minPosition -1
                    maxPosition 1
                  }
                  PositionSensor {
                    name "right_front_wheel_joint_sensor"
                  }
                ]
                endPoint Solid {
                  children [
                    Transform {
                      rotation -0.5773129352569557 0.5773689352506757 0.5773689352506757 2.094284
                      children [
                        Shape {
                          appearance PBRAppearance {
                            baseColor 0.5 0.5 0.5
                            roughness 1
                            metalness 0
                          }
                          geometry Cylinder {
                            height 0.025
                            radius 0.03
                          }
                        }
                      ]
                    }
                  ]
                  name "right_front_wheel"
                  contactMaterial "wheel"
                  boundingObject Transform {
                    rotation -0.5773129352569557 0.5773689352506757 0.5773689352506757 2.094284
                    children [
                      Cylinder {
                        height 0.025
                        radius 0.03
                      }
                    ]
                  }
                  physics Physics {
                    density -1
                    mass 0.042222
                    centerOfMass [
                      0 0 0
                    ]
                    inertiaMatrix [
                      9.44606e-05 6.11771e-05 6.11771e-05
                      -2.083948e-20 -3.206093e-09 7.972411e-21
                    ]
                  }
                }
              }
            ]
            name "right_steering_hinge"
            physics Physics {
              density -1
              mass 0.05
              centerOfMass [
                0 0 0
              ]
              inertiaMatrix [
                4e-06 4e-06 4e-06
                0 0 0
              ]
            }
          }
        }
        Solid {
          translation 0.091711 0.03 0.080023
          rotation 0 1 0 0.2618
          children [
            Shape {
              appearance PBRAppearance {
                baseColor 0.5 0.5 0.5
                roughness 1
                metalness 0
              }
              geometry DEF zed_camera_link_leftcam Mesh {
                url [
                  "/mnt/d/DeepRacer/CAIRORacer/deepracer_ws/install/deepracer_description/share/deepracer_description/meshes/zed_camera_link_leftcam.STL"
                ]
              }
            }
            Solid {
              translation 0.044755 0 0.04
              children [
                Camera {
                  name "zed_camera_left_sensor"
                  fieldOfView 2.094
                  width 160
                  height 120
                }
              ]
              name "camera_link_leftcam"
              physics Physics {
                density -1
                mass 0.001
                centerOfMass [
                  0.0005 0 0
                ]
                inertiaMatrix [
                  1e-06 1e-06 1e-06
                  0 0 0
                ]
              }
            }
          ]
          name "zed_camera_link_leftcam"
          physics Physics {
            density -1
            mass 0.001
            centerOfMass [
              0.019881 6.3e-05 0.034966
            ]
            inertiaMatrix [
              1e-06 1e-06 1e-06
              0 0 0
            ]
          }
        }
        Solid {
          translation 0.091711 -0.03 0.080023
          rotation 0 1 0 0.2618
          children [
            Shape {
              appearance PBRAppearance {
                baseColor 0.5 0.5 0.5
                roughness 1
                metalness 0
              }
              geometry DEF zed_camera_link_rightcam Mesh {
                url [
                  "/mnt/d/DeepRacer/CAIRORacer/deepracer_ws/install/deepracer_description/share/deepracer_description/meshes/zed_camera_link_rightcam.STL"
                ]
              }
            }
            Solid {
              translation 0.044755 0 0.04
              children [
                Camera {
                  name "zed_camera_right_sensor"
                  fieldOfView 2.094
                  width 160
                  height 120
                }
              ]
              name "camera_link_rightcam"
              physics Physics {
                density -1
                mass 0.001
                centerOfMass [
                  0.0005 0 0
                ]
                inertiaMatrix [
                  1e-06 1e-06 1e-06
                  0 0 0
                ]
              }
            }
          ]
          name "zed_camera_link_rightcam"
          physics Physics {
            density -1
            mass 0.001
            centerOfMass [
              0.019881 6.3e-05 0.034966
            ]
            inertiaMatrix [
              1e-06 1e-06 1e-06
              0 0 0
            ]
          }
        }
        Solid {
          translation 0.02913 0 0.16145
          rotation 0 0 1 3.1416
          children [
            Shape {
              appearance PBRAppearance {
                baseColor 0.5 0.5 0.5
                roughness 1
                metalness 0
              }
              geometry DEF laser Mesh {
                url [
                  "/mnt/d/DeepRacer/CAIRORacer/deepracer_ws/install/deepracer_description/share/deepracer_description/meshes/laser.STL"
                ]
              }
            }
            Lidar {
              name "hokuyo_sensor"
              horizontalResolution 667
              fieldOfView 5.23598
              numberOfLayers 1
              near 0.1
              minRange 0.15
              maxRange 12
              noise 0.001
              resolution 0.01
            }
          ]
          name "laser"
          boundingObject USE laser
          physics Physics {
            density -1
            mass 1e-05
            centerOfMass [
              0.006099 0.000284 -0.012654
            ]
            inertiaMatrix [
              1e-06 1e-06 1e-06
              0 0 0
            ]
          }
        }
        Solid {
          translation -0.0762 0 2e-05
          children [
            Shape {
              appearance PBRAppearance {
                baseColor 0.5 0.5 0.5
                roughness 1
                metalness 0
              }
              geometry DEF deepracer Mesh {
                url [
                  "/mnt/d/DeepRacer/CAIRORacer/deepracer_ws/install/deepracer_description/share/deepracer_description/meshes/deepracer.STL"
                ]
              }
            }
          ]
          name "shell"
          boundingObject USE deepracer
          physics Physics {
            centerOfMass [
              0 0 0
            ]
          }
        }
      ]
      name "chassis"
      physics Physics {
        density -1
        mass 1.9068
        centerOfMass [
          0 0 0
        ]
        inertiaMatrix [
          0.004151895 0.01037974 0.01037974
          0 0 0
        ]
      }
    }
  ]
  name "Agent"
  physics Physics {
    density -1
    mass 1e-05
    centerOfMass [
      0 0 0
    ]
  }
  controller "<extern>"
}
